Workbook

Sheet INDEX
E5: Name | F5: Sayali Mhatre
E6: Roll No | F6: 25PGDMFM052
E7: Sector | F7: IT
E8: Company Name | F8: HDFC LIFE
E9: College Name | F9: FIIB

Sheet RSI
B1: IT SECTOR
B3: BUY | H3: SELL
B4: Q1 | H4: Q1
B5: SYMBOL | C5: BACKTEST P&L | D5: TOTAL NUMBER OF TRADES | E5: NUMBER OF WINS | F5: NUMBER OF LOSSES | H5: SYMBOL | I5: BACKTEST P&L | J5: TOTAL NUMBER OF TRADES | K5: NUMBER OF WINS | L5: NUMBER OF LOSSES
B6: TCS | C6: 112.2 | D6: 38 | E6: 17 | F6: =D6-E6 -> 21 | H6: TCS | I6: 815.09 | J6: 39 | K6: 20 | L6: 19
B7: INFY | C7: 815.15 | D7: 36 | E7: 19 | F7: =D7-E7 -> 17 | H7: INFY | I7: 179.84 | J7: 42 | K7: 21 | L7: =J7-K7 -> 21
B8: HCLTECH | C8: 21 | D8: 42 | E8: 23 | F8: =D8-E8 -> 19 | H8: HCLTECH | I8: -278.5 | J8: 48 | K8: 19 | L8: =J8-K8 -> 29
B9: WIPRO | C9: 876.21 | D9: 38 | E9: 19 | F9: =D9-E9 -> 19 | H9: WIPRO | I9: -889.05 | J9: 44 | K9: 19 | L9: =J9-K9 -> 25
B10: TECHM | C10: 417.15 | D10: 40 | E10: 20 | F10: =D10-E10 -> 20 | H10: TECHM | I10: -1591.75 | J10: 63 | K10: 28 | L10: =J10-K10 -> 35
B11: PERSISTENT | C11: -1403.89 | D11: 45 | E11: 14 | F11: =D11-E11 -> 31 | H11: PERSISTENT | I11: -181.4 | J11: 55 | K11: 21 | L11: =J11-K11 -> 34
B12: OFSS | C12: 768.5 | D12: 47 | E12: 22 | F12: =D12-E12 -> 25 | H12: OFSS | I12: 1208.5 | J12: 63 | K12: 32 | L12: =J12-K12 -> 31
B13: COFORGE | C13: 2057.55 | D13: 42 | E13: 20 | F13: =D13-E13 -> 22 | H13: COFORGE | I13: 67.14 | J13: 62 | K13: 27 | L13: =J13-K13 -> 35
B14: MPHASIS | C14: -1262.75 | D14: 51 | E14: 20 | F14: =D14-E14 -> 31 | H14: MPHASIS | I14: 584.45 | J14: 62 | K14: 29 | L14: =J14-K14 -> 33
B15: HEXT | C15: 1471.45 | D15: 57 | E15: 25 | F15: =D15-E15 -> 32 | H15: HEXT | I15: -3022.8 | J15: 60 | K15: 22 | L15: =J15-K15 -> 38
D16: =SUM(D6:D15) -> 436 | E16: =SUM(E6:E15) -> 199 | F16: =SUM(F6:F15) -> 237 | J16: =SUM(J6:J15) -> 538 | K16: =SUM(K6:K15) -> 238 | L16: =SUM(L6:L15) -> 300
B18: Q2 | H18: Q2
B19: SYMBOL | C19: BACKTEST P&L | D19: TOTAL NUMBER OF TRADES | E19: NUMBER OF WINS | F19: NUMBER OF LOSSES | H19: SYMBOL | I19: BACKTEST P&L | J19: TOTAL NUMBER OF TRADES | K19: NUMBER OF WINS | L19: NUMBER OF LOSSES
B20: TCS | C20: -1913.89 | D20: 46 | E20: 18 | F20: =D20-E20 -> 28 | H20: TCS | I20: 670.5 | J20: 34 | K20: 18 | L20: =J20-K20 -> 16
B21: INFY | C21: -1427.49 | D21: 56 | E21: 22 | F21: =D21-E21 -> 34 | H21: INFY | I21: -198.35 | J21: 40 | K21: 24 | L21: =J21-K21 -> 16
B22: HCLTECH | C22: -1093.34 | D22: 57 | E22: 23 | F22: =D22-E22 -> 34 | H22: HCLTECH | I22: 122.3 | J22: 25 | K22: 13 | L22: =J22-K22 -> 12
B23: WIPRO | C23: -1925.96 | D23: 46 | E23: 18 | F23: =D23-E23 -> 28 | H23: WIPRO | I23: 1471.73 | J23: 32 | K23: 20 | L23: =J23-K23 -> 12
B24: TECHM | C24: -1512.94 | D24: 53 | E24: 23 | F24: =D24-E24 -> 30 | H24: TECHM | I24: -1341.75 | J24: 38 | K24: 23 | L24: =J24-K24 -> 15
B25: PERSISTENT | C25: -475.59 | D25: 49 | E25: 19 | F25: =D25-E25 -> 30 | H25: PERSISTENT | I25: 1210.8 | J25: 38 | K25: 21 | L25: =J25-K25 -> 17
B26: OFSS | C26: -457.6 | D26: 55 | E26: 23 | F26: =D26-E26 -> 32 | H26: OFSS | I26: 1752.6 | J26: 35 | K26: 20 | L26: =J26-K26 -> 15
B27: COFORGE | C27: -1585.25 | D27: 57 | E27: 17 | F27: =D27-E27 -> 40 | H27: COFORGE | I27: -177.8 | J27: 47 | K27: 22 | L27: =J27-K27 -> 25
B28: MPHASIS | C28: 734.55 | D28: 47 | E28: 21 | F28: =D28-E28 -> 26 | H28: MPHASIS | I28: 523.94 | J28: 45 | K28: 20 | L28: =J28-K28 -> 25
B29: HEXT | C29: -1326.95 | D29: 64 | E29: 24 | F29: =D29-E29 -> 40 | H29: HEXT | I29: -887.15 | J29: 47 | K29: 18 | L29: =J29-K29 -> 29
D30: =SUM(D20:D29) -> 530 | E30: =SUM(E20:E29) -> 208 | F30: =SUM(F20:F29) -> 322 | J30: =SUM(J20:J29) -> 381 | K30: =SUM(K20:K29) -> 199 | L30: =SUM(L20:L29) -> 182
B32: Q3 | H32: Q3
B33: SYMBOL | C33: BACKTEST P&L | D33: TOTAL NUMBER OF TRADES | E33: NUMBER OF WINS | F33: NUMBER OF LOSSES | H33: SYMBOL | I33: BACKTEST P&L | J33: TOTAL NUMBER OF TRADES | K33: NUMBER OF WINS | L33: NUMBER OF LOSSES
B34: TCS | C34: -388.64 | D34: 31 | E34: 18 | F34: =D34-E34 -> 13 | H34: TCS | I34: -1680.7 | J34: 39 | K34: 16 | L34: =J34-K34 -> 23
B35: INFY | C35: -100.8 | D35: 32 | E35: 18 | F35: =D35-E35 -> 14 | H35: INFY | I35: -1062.55 | J35: 47 | K35: 21 | L35: =J35-K35 -> 26
B36: HCLTECH | C36: 37.75 | D36: 57 | E36: 23 | F36: =D36-E36 -> 34 | H36: HCLTECH | I36: -1341.85 | J36: 46 | K36: 17 | L36: =J36-K36 -> 29
B37: WIPRO | C37: 306.54 | D37: 23 | E37: 15 | F37: =D37-E37 -> 8 | H37: WIPRO | I37: -199.58 | J37: 46 | K37: 25 | L37: =J37-K37 -> 21
B38: TECHM | C38: -416.6 | D38: 30 | E38: 11 | F38: =D38-E38 -> 19 | H38: TECHM | I38: -672.4 | J38: 35 | K38: 17 | L38: =J38-K38 -> 18
B39: PERSISTENT | C39: -2444.85 | D39: 47 | E39: 16 | F39: =D39-E39 -> 31 | H39: PERSISTENT | I39: 429.35 | J39: 40 | K39: 18 | L39: =J39-K39 -> 22
B40: OFSS | C40: 746.2 | D40: 36 | E40: 19 | F40: =D40-E40 -> 17 | H40: OFSS | I40: -1303.65 | J40: 41 | K40: 13 | L40: =J40-K40 -> 28
B41: COFORGE | C41: -917.65 | D41: 40 | E41: 18 | F41: =D41-E41 -> 22 | H41: COFORGE | I41: -1651.25 | J41: 51 | K41: 22 | L41: =J41-K41 -> 29
B42: MPHASIS | C42: 734.55 | D42: 51 | E42: 20 | F42: =D42-E42 -> 31 | H42: MPHASIS | I42: -238.8 | J42: 40 | K42: 19 | L42: =J42-K42 -> 21
B43: HEXT | C43: -1326.95 | D43: 51 | E43: 21 | F43: =D43-E43 -> 30 | H43: HEXT | I43: -5040.45 | J43: 63 | K43: 15 | L43: =J43-K43 -> 48
...

Sheet Supertrend
B1: IT SECTOR
B3: BUY | H3: SELL
B4: Q1 | H4: Q1
B5: SYMBOL | C5: BACKTEST P&L | D5: TOTAL NUMBER OF TRADES | E5: NUMBER OF WINS | F5: NUMBER OF LOSSES | H5: SYMBOL | I5: BACKTEST P&L | J5: TOTAL NUMBER OF TRADES | K5: NUMBER OF WINS | L5: NUMBER OF LOSSES
B6: TCS | C6: -392.24 | D6: 35 | E6: 16 | F6: 19 | H6: TCS | I6: 812 | J6: 31 | K6: 16 | L6: 15
B7: INFY | C7: 1130.1 | D7: 36 | E7: 20 | F7: 16 | H7: INFY | I7: 661.3 | J7: 40 | K7: 20 | L7: 20
B8: HCLTECH | C8: 183.9 | D8: 41 | E8: 19 | F8: 22 | H8: HCLTECH | I8: -566.65 | J8: 47 | K8: 19 | L8: 28
B9: WIPRO | C9: 1467.95 | D9: 31 | E9: 16 | F9: 15 | H9: WIPRO | I9: -953.8 | J9: 43 | K9: 20 | L9: 23
B10: TECHM | C10: 524 | D10: 28 | E10: 13 | F10: 15 | H10: TECHM | I10: -1433.55 | J10: 57 | K10: 24 | L10: 33
B11: PERSISTENT | C11: 158.3 | D11: 38 | E11: 15 | F11: 23 | H11: PERSISTENT | I11: -299.35 | J11: 57 | K11: 22 | L11: 35
B12: OFSS | C12: -676.09 | D12: 39 | E12: 15 | F12: 24 | H12: OFSS | I12: 785.89 | J12: 38 | K12: 17 | L12: 21
B13: COFORGE | C13: -923.65 | D13: 43 | E13: 15 | F13: 28 | H13: COFORGE | I13: 979.64 | J13: 58 | K13: 26 | L13: 32
B14: MPHASIS | C14: 255.85 | D14: 70 | E14: 31 | F14: =D14-E14 -> 39 | H14: MPHASIS | I14: -1547.3 | J14: 79 | K14: 30 | L14: =J14-K14 -> 49
B15: HEXT | C15: 4726.88 | D15: 82 | E15: 40 | F15: =D15-E15 -> 42 | H15: HEXT | I15: -4590.1 | J15: 78 | K15: 27 | L15: =J15-K15 -> 51
D16: =SUM(D6:D15) -> 443 | E16: =SUM(E6:E15) -> 200 | F16: =SUM(F6:F15) -> 243 | J16: =SUM(J6:J15) -> 528 | K16: =SUM(K6:K15) -> 221 | L16: =SUM(L6:L15) -> 307
B18: Q2 | H18: Q2
B19: SYMBOL | C19: BACKTEST P&L | D19: TOTAL NUMBER OF TRADES | E19: NUMBER OF WINS | F19: NUMBER OF LOSSES | H19: SYMBOL | I19: BACKTEST P&L | J19: TOTAL NUMBER OF TRADES | K19: NUMBER OF WINS | L19: NUMBER OF LOSSES
B20: TCS | C20: -2547.4 | D20: 39 | E20: 12 | F20: 27 | H20: TCS | I20: 172.95 | J20: 32 | K20: 14 | L20: 18
B21: INFY | C21: -1201.4 | D21: 51 | E21: 21 | F21: 30 | H21: INFY | I21: 239.69 | J21: 33 | K21: 18 | L21: 15
B22: HCLTECH | C22: -769.6 | D22: 54 | E22: 25 | F22: 29 | H22: HCLTECH | I22: 89.49 | J22: 22 | K22: 10 | L22: 12
B23: WIPRO | C23: -1563.25 | D23: 41 | E23: 20 | F23: 21 | H23: WIPRO | I23: 757.65 | J23: 33 | K23: 21 | L23: 12
B24: TECHM | C24: -1159.3 | D24: 50 | E24: 21 | F24: 29 | H24: TECHM | I24: -749.35 | J24: 31 | K24: 13 | L24: 18
B25: PERSISTENT | C25: 106.3 | D25: 42 | E25: 18 | F25: 24 | H25: PERSISTENT | I25: 996.89 | J25: 33 | K25: 18 | L25: 15
B26: OFSS | C26: 399.65 | D26: 46 | E26: 22 | F26: 24 | H26: OFSS | I26: 261.19 | J26: 41 | K26: 19 | L26: 22
B27: COFORGE | C27: 103.75 | D27: 49 | E27: 20 | F27: 29 | H27: COFORGE | I27: 79.09 | J27: 40 | K27: 17 | L27: 23
B28: MPHASIS | C28: -2045.34 | D28: 72 | E28: 23 | F28: =D28-E28 -> 49 | H28: MPHASIS | I28: 469.54 | J28: 78 | K28: 35 | L28: =J28-K28 -> 43
B29: HEXT | C29: -676.39 | D29: 85 | E29: 32 | F29: =D29-E29 -> 53 | H29: HEXT | I29: -1696.5 | J29: 77 | K29: 27 | L29: =J29-K29 -> 50
D30: =SUM(D20:D29) -> 529 | E30: =SUM(E20:E29) -> 214 | F30: =SUM(F20:F29) -> 315 | J30: =SUM(J20:J29) -> 420 | K30: =SUM(K20:K29) -> 192 | L30: =SUM(L20:L29) -> 228
B32: Q3 | H32: Q3
B33: SYMBOL | C33: BACKTEST P&L | D33: TOTAL NUMBER OF TRADES | E33: NUMBER OF WINS | F33: NUMBER OF LOSSES | H33: SYMBOL | I33: BACKTEST P&L | J33: TOTAL NUMBER OF TRADES | K33: NUMBER OF WINS | L33: NUMBER OF LOSSES
B34: TCS | C34: -520.6 | D34: 28 | E34: 15 | F34: 13 | H34: TCS | I34: -2039 | J34: 41 | K34: 15 | L34: 26
B35: INFY | C35: 290 | D35: 34 | E35: 17 | F35: 17 | H35: INFY | I35: -1203 | J35: 45 | K35: 21 | L35: 24
B36: HCLTECH | C36: -292.8 | D36: 30 | E36: 15 | F36: 15 | H36: HCLTECH | I36: -1412 | J36: 39 | K36: 12 | L36: 27
B37: WIPRO | C37: 468.7 | D37: 21 | E37: 14 | F37: 7 | H37: WIPRO | I37: -1101.75 | J37: 46 | K37: 22 | L37: 24
B38: TECHM | C38: -321.9 | D38: 26 | E38: 9 | F38: 17 | H38: TECHM | I38: -655.63 | J38: 33 | K38: 17 | L38: 16
B39: PERSISTENT | C39: -1613.6 | D39: 36 | E39: 14 | F39: 22 | H39: PERSISTENT | I39: -878.29 | J39: 27 | K39: 10 | L39: 17
B40: OFSS | C40: 165.35 | D40: 44 | E40: 21 | F40: 23 | H40: OFSS | I40: 720.74 | J40: 36 | K40: 18 | L40: 18
B41: COFORGE | C41: -77.79 | D41: 40 | E41: 17 | F41: 23 | H41: COFORGE | I41: 411.64 | J41: 39 | K41: 20 | L41: 19
B42: MPHASIS | C42: -634.49 | D42: 61 | E42: 32 | F42: =D42-E42 -> 29 | H42: MPHASIS | I42: -1373.4 | J42: 67 | K42: 27 | L42: =J42-K42 -> 40
B43: HEXT | C43: -1130.69 | D43: 66 | E43: 25 | F43: =D43-E43 -> 41 | H43: HEXT | I43: -4339.95 | J43: 84 | K43: 29 | L43: =J43-K43 -> 55
...

Sheet MA
B1: IT SECTOR
B3: BUY | H3: SELL
B4: Q1 | H4: Q1
B5: SYMBOL | C5: BACKTEST P&L | D5: TOTAL NUMBER OF TRADES | E5: NUMBER OF WINS | F5: NUMBER OF LOSSES | H5: SYMBOL | I5: BACKTEST P&L | J5: TOTAL NUMBER OF TRADES | K5: NUMBER OF WINS | L5: NUMBER OF LOSSES
B6: TCS | C6: -357.69 | D6: 50 | E6: 23 | F6: =D6-E6 -> 27 | H6: TCS | I6: 529 | J6: 49 | K6: 26 | L6: 19
B7: INFY | C7: 1560.85 | D7: 53 | E7: 30 | F7: =D7-E7 -> 23 | H7: INFY | I7: -1390.35 | J7: 56 | K7: 25 | L7: =J7-K7 -> 31
B8: HCLTECH | C8: 484.95 | D8: 53 | E8: 24 | F8: =D8-E8 -> 29 | H8: HCLTECH | I8: 36.35 | J8: 51 | K8: 24 | L8: =J8-K8 -> 27
B9: WIPRO | C9: 63.49 | D9: 49 | E9: 22 | F9: =D9-E9 -> 27 | H9: WIPRO | I9: -827.84 | J9: 46 | K9: 21 | L9: =J9-K9 -> 25
B10: TECHM | C10: 1846.75 | D10: 50 | E10: 27 | F10: =D10-E10 -> 23 | H10: TECHM | I10: 216.7 | J10: 48 | K10: 23 | L10: =J10-K10 -> 25
B11: PERSISTENT | C11: -70.7 | D11: 51 | E11: 23 | F11: =D11-E11 -> 28 | H11: PERSISTENT | I11: 1373.6 | J11: 57 | K11: 31 | L11: =J11-K11 -> 26
B12: OFSS | C12: -1126.55 | D12: 54 | E12: 22 | F12: =D12-E12 -> 32 | H12: OFSS | I12: 1142.3 | J12: 53 | K12: 25 | L12: =J12-K12 -> 28
B13: COFORGE | C13: 562.4 | D13: 50 | E13: 27 | F13: =D13-E13 -> 23 | H13: COFORGE | I13: 1255.35 | J13: 49 | K13: 23 | L13: =J13-K13 -> 26
B14: MPHASIS | C14: 2255.5 | D14: 47 | E14: 26 | F14: =D14-E14 -> 21 | H14: MPHASIS | I14: 195.15 | J14: 50 | K14: 27 | L14: =J14-K14 -> 23
B15: HEXT | C15: 2250.4 | D15: 49 | E15: 25 | F15: =D15-E15 -> 24 | H15: HEXT | I15: -44.55 | J15: 52 | K15: 23 | L15: =J15-K15 -> 29
D16: =SUM(D6:D15) -> 506 | E16: =SUM(E6:E15) -> 249 | F16: =SUM(F6:F15) -> 257 | J16: =SUM(J6:J15) -> 511 | K16: =SUM(K6:K15) -> 248 | L16: =SUM(L6:L15) -> 259
B18: Q2 | H18: Q2
B19: SYMBOL | C19: BACKTEST P&L | D19: TOTAL NUMBER OF TRADES | E19: NUMBER OF WINS | F19: NUMBER OF LOSSES | H19: SYMBOL | I19: BACKTEST P&L | J19: TOTAL NUMBER OF TRADES | K19: NUMBER OF WINS | L19: NUMBER OF LOSSES
B20: TCS | C20: -651.45 | D20: 47 | E20: 16 | F20: =D20-E20 -> 31 | H20: TCS | I20: 813.1 | J20: 43 | K20: 26 | L20: =J20-K20 -> 17
B21: INFY | C21: 933.1 | D21: 50 | E21: 24 | F21: =D21-E21 -> 26 | H21: INFY | I21: 808.5 | J21: 47 | K21: 28 | L21: =J21-K21 -> 19
B22: HCLTECH | C22: -200.85 | D22: 49 | E22: 27 | F22: =D22-E22 -> 22 | H22: HCLTECH | I22: 798.1 | J22: 47 | K22: 24 | L22: =J22-K22 -> 23
B23: WIPRO | C23: -556.42 | D23: 53 | E23: 23 | F23: =D23-E23 -> 30 | H23: WIPRO | I23: 584.28 | J23: 48 | K23: 25 | L23: =J23-K23 -> 23
B24: TECHM | C24: 851.4 | D24: 49 | E24: 26 | F24: =D24-E24 -> 23 | H24: TECHM | I24: -879.4 | J24: 47 | K24: 18 | L24: =J24-K24 -> 29
B25: PERSISTENT | C25: -1637.65 | D25: 55 | E25: 21 | F25: =D25-E25 -> 34 | H25: PERSISTENT | I25: 69.1 | J25: 52 | K25: 27 | L25: =J25-K25 -> 25
B26: OFSS | C26: -1187.05 | D26: 55 | E26: 21 | F26: =D26-E26 -> 34 | H26: OFSS | I26: 568.15 | J26: 48 | K26: 22 | L26: =J26-K26 -> 26
B27: COFORGE | C27: 128.3 | D27: 49 | E27: 25 | F27: =D27-E27 -> 24 | H27: COFORGE | I27: 656.35 | J27: 57 | K27: 26 | L27: =J27-K27 -> 31
B28: MPHASIS | C28: -901.3 | D28: 55 | E28: 22 | F28: =D28-E28 -> 33 | H28: MPHASIS | I28: -436.85 | J28: 49 | K28: 25 | L28: =J28-K28 -> 24
B29: HEXT | C29: -393.9 | D29: 50 | E29: 19 | F29: =D29-E29 -> 31 | H29: HEXT | I29: 1563.45 | J29: 47 | K29: 18 | L29: =J29-K29 -> 29
D30: =SUM(D20:D29) -> 512 | E30: =SUM(E20:E29) -> 224 | F30: =SUM(F20:F29) -> 288 | J30: =SUM(J20:J29) -> 485 | K30: =SUM(K20:K29) -> 239 | L30: =SUM(L20:L29) -> 246
B32: Q3 | H32: Q3
B33: SYMBOL | C33: BACKTEST P&L | D33: TOTAL NUMBER OF TRADES | E33: NUMBER OF WINS | F33: NUMBER OF LOSSES | H33: SYMBOL | I33: BACKTEST P&L | J33: TOTAL NUMBER OF TRADES | K33: NUMBER OF WINS | L33: NUMBER OF LOSSES
B34: TCS | C34: 582 | D34: 46 | E34: 23 | F34: =D34-E34 -> 23 | H34: TCS | I34: -509.14 | J34: 49 | K34: 27 | L34: =J34-K34 -> 22
B35: INFY | C35: -28.85 | D35: 47 | E35: 25 | F35: =D35-E35 -> 22 | H35: INFY | I35: -285.4 | J35: 50 | K35: 23 | L35: =J35-K35 -> 27
B36: HCLTECH | C36: 464.2 | D36: 46 | E36: 27 | F36: =D36-E36 -> 19 | H36: HCLTECH | I36: -895.55 | J36: 48 | K36: 18 | L36: =J36-K36 -> 30
B37: WIPRO | C37: 389.4 | D37: 49 | E37: 25 | F37: =D37-E37 -> 24 | H37: WIPRO | I37: -358.88 | J37: 51 | K37: 22 | L37: =J37-K37 -> 29
B38: TECHM | C38: 862.8 | D38: 44 | E38: 24 | F38: =D38-E38 -> 20 | H38: TECHM | I38: 58 | J38: 46 | K38: 25 | L38: =J38-K38 -> 21
B39: PERSISTENT | C39: -453.95 | D39: 47 | E39: 21 | F39: =D39-E39 -> 26 | H39: PERSISTENT | I39: 802.8 | J39: 46 | K39: 24 | L39: =J39-K39 -> 22
B40: OFSS | C40: -1119.35 | D40: 50 | E40: 17 | F40: =D40-E40 -> 33 | H40: OFSS | I40: -825.1 | J40: 50 | K40: 19 | L40: =J40-K40 -> 31
B41: COFORGE | C41: -1230.85 | D41: 59 | E41: 22 | F41: =D41-E41 -> 37 | H41: COFORGE | I41: 13.45 | J41: 57 | K41: 28 | L41: =J41-K41 -> 29
B42: MPHASIS | C42: 842.35 | D42: 51 | E42: 26 | F42: =D42-E42 -> 25 | H42: MPHASIS | I42: -836.7 | J42: 60 | K42: 24 | L42: =J42-K42 -> 36
B43: HEXT | C43: 2496.65 | D43: 48 | E43: 24 | F43: =D43-E43 -> 24 | H43: HEXT | I43: -528.7 | J43: 47 | K43: 20 | L43: =J43-K43 -> 27
...

Sheet VWAP
B1: IT SECTOR
B3: BUY | H3: SELL
B4: Q1 | H4: Q1
B5: SYMBOL | C5: BACKTEST P&L | D5: TOTAL NUMBER OF TRADES | E5: NUMBER OF WINS | F5: NUMBER OF LOSSES | H5: SYMBOL | I5: BACKTEST P&L | J5: TOTAL NUMBER OF TRADES | K5: NUMBER OF WINS | L5: NUMBER OF LOSSES
B6: TCS | C6: 395.2 | D6: 63 | E6: 34 | F6: =D6-E6 -> 29 | H6: TCS | I6: 526.3 | J6: 66 | K6: 32 | L6: 19
B7: INFY | C7: 214.55 | D7: 70 | E7: 37 | F7: =D7-E7 -> 33 | H7: INFY | I7: 766.5 | J7: 70 | K7: 34 | L7: =J7-K7 -> 36
B8: HCLTECH | C8: 2534 | D8: 75 | E8: 36 | F8: =D8-E8 -> 39 | H8: HCLTECH | I8: 3259.3 | J8: 73 | K8: 42 | L8: =J8-K8 -> 31
B9: WIPRO | C9: 285.4 | D9: 71 | E9: 47 | F9: =D9-E9 -> 24 | H9: WIPRO | I9: 608.61 | J9: 76 | K9: 35 | L9: =J9-K9 -> 41
B10: TECHM | C10: 858.85 | D10: 79 | E10: 39 | F10: =D10-E10 -> 40 | H10: TECHM | I10: 1753.05 | J10: 82 | K10: 40 | L10: =J10-K10 -> 42
B11: PERSISTENT | C11: 262.6 | D11: 78 | E11: 32 | F11: =D11-E11 -> 46 | H11: PERSISTENT | I11: -665.95 | J11: 89 | K11: 31 | L11: =J11-K11 -> 58
B12: OFSS | C12: 1417.3 | D12: 89 | E12: 41 | F12: =D12-E12 -> 48 | H12: OFSS | I12: 857.2 | J12: 96 | K12: 41 | L12: =J12-K12 -> 55
B13: COFORGE | C13: 1614.45 | D13: 89 | E13: 39 | F13: =D13-E13 -> 50 | H13: COFORGE | I13: 2423.1 | J13: 97 | K13: 47 | L13: =J13-K13 -> 50
B14: MPHASIS | C14: 3944 | D14: 94 | E14: 50 | F14: =D14-E14 -> 44 | H14: MPHASIS | I14: 2639.2 | J14: 96 | K14: 44 | L14: =J14-K14 -> 52
B15: HEXT | C15: 10162.55 | D15: 95 | E15: 56 | F15: =D15-E15 -> 39 | H15: HEXT | I15: 7376 | J15: 90 | K15: 46 | L15: =J15-K15 -> 44
D16: =SUM(D6:D15) -> 803 | E16: =SUM(E6:E15) -> 411 | F16: =SUM(F6:F15) -> 392 | J16: =SUM(J6:J15) -> 835 | K16: =SUM(K6:K15) -> 392 | L16: =SUM(L6:L15) -> 428
B18: Q2 | H18: Q2
B19: SYMBOL | C19: BACKTEST P&L | D19: TOTAL NUMBER OF TRADES | E19: NUMBER OF WINS | F19: NUMBER OF LOSSES | H19: SYMBOL | I19: BACKTEST P&L | J19: TOTAL NUMBER OF TRADES | K19: NUMBER OF WINS | L19: NUMBER OF LOSSES
B20: TCS | C20: -3036.59 | D20: 66 | E20: 21 | F20: =D20-E20 -> 45 | H20: TCS | I20: -3204.39 | J20: 66 | K20: 20 | L20: =J20-K20 -> 46
B21: INFY | C21: -1834.95 | D21: 67 | E21: 25 | F21: =D21-E21 -> 42 | H21: INFY | I21: -1960.35 | J21: 71 | K21: 25 | L21: =J21-K21 -> 46
B22: HCLTECH | C22: -1843.75 | D22: 69 | E22: 25 | F22: =D22-E22 -> 44 | H22: HCLTECH | I22: -2601.4 | J22: 76 | K22: 30 | L22: =J22-K22 -> 46
B23: WIPRO | C23: -1919.13 | D23: 67 | E23: 24 | F23: =D23-E23 -> 43 | H23: WIPRO | I23: -1637.06 | J23: 72 | K23: 29 | L23: =J23-K23 -> 43
B24: TECHM | C24: -914.65 | D24: 69 | E24: 31 | F24: =D24-E24 -> 38 | H24: TECHM | I24: -1466.25 | J24: 76 | K24: 33 | L24: =J24-K24 -> 43
B25: PERSISTENT | C25: -2040.25 | D25: 74 | E25: 24 | F25: =D25-E25 -> 50 | H25: PERSISTENT | I25: -1640.7 | J25: 86 | K25: 34 | L25: =J25-K25 -> 52
B26: OFSS | C26: -2724.1 | D26: 76 | E26: 23 | F26: =D26-E26 -> 53 | H26: OFSS | I26: -2274.7 | J26: 79 | K26: 28 | L26: =J26-K26 -> 51
B27: COFORGE | C27: -2231.7 | D27: 82 | E27: 32 | F27: =D27-E27 -> 50 | H27: COFORGE | I27: -1432.75 | J27: 88 | K27: 33 | L27: =J27-K27 -> 55
B28: MPHASIS | C28: -1905.95 | D28: 86 | E28: 29 | F28: =D28-E28 -> 57 | H28: MPHASIS | I28: -2449.85 | J28: 94 | K28: 34 | L28: =J28-K28 -> 60
B29: HEXT | C29: -1611.25 | D29: 84 | E29: 30 | F29: =D29-E29 -> 54 | H29: HEXT | I29: 1833.75 | J29: 93 | K29: 41 | L29: =J29-K29 -> 52
D30: =SUM(D20:D29) -> 740 | E30: =SUM(E20:E29) -> 264 | F30: =SUM(F20:F29) -> 476 | J30: =SUM(J20:J29) -> 801 | K30: =SUM(K20:K29) -> 307 | L30: =SUM(L20:L29) -> 494
B32: Q3 | H32: Q3
B33: SYMBOL | C33: BACKTEST P&L | D33: TOTAL NUMBER OF TRADES | E33: NUMBER OF WINS | F33: NUMBER OF LOSSES | H33: SYMBOL | I33: BACKTEST P&L | J33: TOTAL NUMBER OF TRADES | K33: NUMBER OF WINS | L33: NUMBER OF LOSSES
B34: TCS | C34: 56.8 | D34: 61 | E34: 28 | F34: =D34-E34 -> 33 | H34: TCS | I34: 1230.4 | J34: 62 | K34: 30 | L34: =J34-K34 -> 32
B35: INFY | C35: 721.85 | D35: 69 | E35: 34 | F35: =D35-E35 -> 35 | H35: INFY | I35: 299.75 | J35: 72 | K35: 39 | L35: =J35-K35 -> 33
B36: HCLTECH | C36: 789.2 | D36: 70 | E36: 37 | F36: =D36-E36 -> 33 | H36: HCLTECH | I36: 853.05 | J36: 74 | K36: 37 | L36: =J36-K36 -> 37
B37: WIPRO | C37: 1712.73 | D37: 67 | E37: 32 | F37: =D37-E37 -> 35 | H37: WIPRO | I37: 182.17 | J37: 69 | K37: 31 | L37: =J37-K37 -> 38
B38: TECHM | C38: 311.45 | D38: 67 | E38: 35 | F38: =D38-E38 -> 32 | H38: TECHM | I38: -71.1 | J38: 70 | K38: 33 | L38: =J38-K38 -> 37
B39: PERSISTENT | C39: -660.2 | D39: 65 | E39: 28 | F39: =D39-E39 -> 37 | H39: PERSISTENT | I39: -1138.2 | J39: 71 | K39: 29 | L39: =J39-K39 -> 42
B40: OFSS | C40: -364.15 | D40: 73 | E40: 32 | F40: =D40-E40 -> 41 | H40: OFSS | I40: 307.35 | J40: 79 | K40: 34 | L40: =J40-K40 -> 45
B41: COFORGE | C41: -839.4 | D41: 74 | E41: 30 | F41: =D41-E41 -> 44 | H41: COFORGE | I41: -220.9 | J41: 80 | K41: 31 | L41: =J41-K41 -> 49
B42: MPHASIS | C42: 1167.3 | D42: 76 | E42: 37 | F42: =D42-E42 -> 39 | H42: MPHASIS | I42: 2217.25 | J42: 76 | K42: 39 | L42: =J42-K42 -> 37
B43: HEXT | C43: 2156.55 | D43: 80 | E43: 35 | F43: =D43-E43 -> 45 | H43: HEXT | I43: 5276.9 | J43: 76 | K43: 38 | L43: =J43-K43 -> 38
...

Sheet MACD
B1: IT SECTOR
B3: BUY | H3: SELL
B4: Q1 | H4: Q1
B5: SYMBOL | C5: BACKTEST P&L | D5: TOTAL NUMBER OF TRADES | E5: NUMBER OF WINS | F5: NUMBER OF LOSSES | H5: SYMBOL | I5: BACKTEST P&L | J5: TOTAL NUMBER OF TRADES | K5: NUMBER OF WINS | L5: NUMBER OF LOSSES
B6: TCS | C6: -289.49 | D6: 79 | E6: 38 | F6: =D6-E6 -> 41 | H6: TCS | I6: 526.3 | J6: 66 | K6: 32 | L6: 19
B7: INFY | C7: 2721.5 | D7: 76 | E7: 41 | F7: =D7-E7 -> 35 | H7: INFY | I7: 766.5 | J7: 70 | K7: 34 | L7: =J7-K7 -> 36
B8: HCLTECH | C8: 639.4 | D8: 82 | E8: 39 | F8: =D8-E8 -> 43 | H8: HCLTECH | I8: 3259.3 | J8: 73 | K8: 42 | L8: =J8-K8 -> 31
B9: WIPRO | C9: 1140.93 | D9: 88 | E9: 40 | F9: =D9-E9 -> 48 | H9: WIPRO | I9: 608.61 | J9: 76 | K9: 35 | L9: =J9-K9 -> 41
B10: TECHM | C10: 1569.75 | D10: 91 | E10: 46 | F10: =D10-E10 -> 45 | H10: TECHM | I10: 1753.05 | J10: 82 | K10: 40 | L10: =J10-K10 -> 42
B11: PERSISTENT | C11: -1184.39 | D11: 102 | E11: 43 | F11: =D11-E11 -> 59 | H11: PERSISTENT | I11: -665.95 | J11: 89 | K11: 31 | L11: =J11-K11 -> 58
B12: OFSS | C12: 3053.85 | D12: 106 | E12: 50 | F12: =D12-E12 -> 56 | H12: OFSS | I12: 857.2 | J12: 96 | K12: 41 | L12: =J12-K12 -> 55
B13: COFORGE | C13: 4633.5 | D13: 105 | E13: 55 | F13: =D13-E13 -> 50 | H13: COFORGE | I13: 2423.1 | J13: 97 | K13: 47 | L13: =J13-K13 -> 50
B14: MPHASIS | C14: 3472.6 | D14: 104 | E14: 52 | F14: =D14-E14 -> 52 | H14: MPHASIS | I14: 2639.2 | J14: 96 | K14: 44 | L14: =J14-K14 -> 52
B15: HEXT | C15: 3856.35 | D15: 103 | E15: 47 | F15: =D15-E15 -> 56 | H15: HEXT | I15: 7376 | J15: 90 | K15: 46 | L15: =J15-K15 -> 44
D16: =SUM(D6:D15) -> 936 | E16: =SUM(E6:E15) -> 451 | F16: =SUM(F6:F15) -> 485 | J16: =SUM(J6:J15) -> 835 | K16: =SUM(K6:K15) -> 392 | L16: =SUM(L6:L15) -> 428
B18: Q2 | H18: Q2
B19: SYMBOL | C19: BACKTEST P&L | D19: TOTAL NUMBER OF TRADES | E19: NUMBER OF WINS | F19: NUMBER OF LOSSES | H19: SYMBOL | I19: BACKTEST P&L | J19: TOTAL NUMBER OF TRADES | K19: NUMBER OF WINS | L19: NUMBER OF LOSSES
B20: TCS | C20: -2642.79 | D20: 76 | E20: 31 | F20: =D20-E20 -> 45 | H20: TCS | I20: -3204.39 | J20: 66 | K20: 20 | L20: =J20-K20 -> 46
B21: INFY | C21: -797.9 | D21: 79 | E21: 34 | F21: =D21-E21 -> 45 | H21: INFY | I21: -1960.35 | J21: 71 | K21: 25 | L21: =J21-K21 -> 46
B22: HCLTECH | C22: -756.69 | D22: 83 | E22: 38 | F22: =D22-E22 -> 45 | H22: HCLTECH | I22: -2601.4 | J22: 76 | K22: 30 | L22: =J22-K22 -> 46
B23: WIPRO | C23: -1371.35 | D23: 82 | E23: 33 | F23: =D23-E23 -> 49 | H23: WIPRO | I23: -1637.06 | J23: 72 | K23: 29 | L23: =J23-K23 -> 43
B24: TECHM | C24: -301.69 | D24: 91 | E24: 42 | F24: =D24-E24 -> 49 | H24: TECHM | I24: -1466.25 | J24: 76 | K24: 33 | L24: =J24-K24 -> 43
B25: PERSISTENT | C25: -2761.19 | D25: 102 | E25: 39 | F25: =D25-E25 -> 63 | H25: PERSISTENT | I25: -1640.7 | J25: 86 | K25: 34 | L25: =J25-K25 -> 52
B26: OFSS | C26: -267.14 | D26: 95 | E26: 41 | F26: =D26-E26 -> 54 | H26: OFSS | I26: -2274.7 | J26: 79 | K26: 28 | L26: =J26-K26 -> 51
B27: COFORGE | C27: -1325.89 | D27: 106 | E27: 43 | F27: =D27-E27 -> 63 | H27: COFORGE | I27: -1432.75 | J27: 88 | K27: 33 | L27: =J27-K27 -> 55
B28: MPHASIS | C28: -531.79 | D28: 105 | E28: 45 | F28: =D28-E28 -> 60 | H28: MPHASIS | I28: -2449.85 | J28: 94 | K28: 34 | L28: =J28-K28 -> 60
B29: HEXT | C29: -419.64 | D29: 106 | E29: 40 | F29: =D29-E29 -> 66 | H29: HEXT | I29: 1833.75 | J29: 93 | K29: 41 | L29: =J29-K29 -> 52
D30: =SUM(D20:D29) -> 925 | E30: =SUM(E20:E29) -> 386 | F30: =SUM(F20:F29) -> 539 | J30: =SUM(J20:J29) -> 801 | K30: =SUM(K20:K29) -> 307 | L30: =SUM(L20:L29) -> 494
B32: Q3 | H32: Q3
B33: SYMBOL | C33: BACKTEST P&L | D33: TOTAL NUMBER OF TRADES | E33: NUMBER OF WINS | F33: NUMBER OF LOSSES | H33: SYMBOL | I33: BACKTEST P&L | J33: TOTAL NUMBER OF TRADES | K33: NUMBER OF WINS | L33: NUMBER OF LOSSES
B34: TCS | C34: -119.34 | D34: 75 | E34: 36 | F34: =D34-E34 -> 39 | H34: TCS | I34: 1230.4 | J34: 62 | K34: 30 | L34: =J34-K34 -> 32
B35: INFY | C35: 1968.75 | D35: 75 | E35: 45 | F35: =D35-E35 -> 30 | H35: INFY | I35: 299.75 | J35: 72 | K35: 39 | L35: =J35-K35 -> 33
B36: HCLTECH | C36: 1742.2 | D36: 71 | E36: 40 | F36: =D36-E36 -> 31 | H36: HCLTECH | I36: 853.05 | J36: 74 | K36: 37 | L36: =J36-K36 -> 37
B37: WIPRO | C37: 568.82 | D37: 69 | E37: 35 | F37: =D37-E37 -> 34 | H37: WIPRO | I37: 182.17 | J37: 69 | K37: 31 | L37: =J37-K37 -> 38
B38: TECHM | C38: 311.45 | D38: 67 | E38: 35 | F38: =D38-E38 -> 32 | H38: TECHM | I38: -71.1 | J38: 70 | K38: 33 | L38: =J38-K38 -> 37
B39: PERSISTENT | C39: -660.2 | D39: 65 | E39: 28 | F39: =D39-E39 -> 37 | H39: PERSISTENT | I39: -1138.2 | J39: 71 | K39: 29 | L39: =J39-K39 -> 42
B40: OFSS | C40: -364.15 | D40: 73 | E40: 32 | F40: =D40-E40 -> 41 | H40: OFSS | I40: 307.35 | J40: 79 | K40: 34 | L40: =J40-K40 -> 45
B41: COFORGE | C41: -839.4 | D41: 74 | E41: 30 | F41: =D41-E41 -> 44 | H41: COFORGE | I41: -220.9 | J41: 80 | K41: 31 | L41: =J41-K41 -> 49
B42: MPHASIS | C42: 1167.3 | D42: 76 | E42: 37 | F42: =D42-E42 -> 39 | H42: MPHASIS | I42: 2217.25 | J42: 76 | K42: 39 | L42: =J42-K42 -> 37
B43: HEXT | C43: 2156.55 | D43: 80 | E43: 35 | F43: =D43-E43 -> 45 | H43: HEXT | I43: 5276.9 | J43: 76 | K43: 38 | L43: =J43-K43 -> 38
...

Sheet Stochastic RSI
B1: IT SECTOR
B3: BUY | H3: SELL
B4: Q1 | H4: Q1
B5: SYMBOL | C5: BACKTEST P&L | D5: TOTAL NUMBER OF TRADES | E5: NUMBER OF WINS | F5: NUMBER OF LOSSES | H5: SYMBOL | I5: BACKTEST P&L | J5: TOTAL NUMBER OF TRADES | K5: NUMBER OF WINS | L5: NUMBER OF LOSSES
B6: TCS | C6: -652.14 | D6: 69 | E6: 31 | F6: 38 | H6: TCS | I6: 2094.95 | J6: 70 | K6: 39 | L6: 31
B7: INFY | C7: 1718.89 | D7: 68 | E7: 36 | F7: 32 | H7: INFY | I7: -162.7 | J7: 74 | K7: 41 | L7: 33
B8: HCLTECH | C8: 1044.6 | D8: 75 | E8: 39 | F8: 36 | H8: HCLTECH | I8: 2423.94 | J8: 73 | K8: 35 | L8: 38
B9: WIPRO | C9: 1733.77 | D9: 69 | E9: 34 | F9: 35 | H9: WIPRO | I9: 3202.08 | J9: 68 | K9: 40 | L9: 28
B10: TECHM | C10: 1035.85 | D10: 74 | E10: 40 | F10: 34 | H10: TECHM | I10: 1736.59 | J10: 78 | K10: 39 | L10: 39
B11: PERSISTENT | C11: 1802.3 | D11: 90 | E11: 46 | F11: 44 | H11: PERSISTENT | I11: -764.4 | J11: 85 | K11: 35 | L11: 50
B12: OFSS | C12: -1171.89 | D12: 79 | E12: 38 | F12: 41 | H12: OFSS | I12: -136.8 | J12: 75 | K12: 39 | L12: 36
B13: COFORGE | C13: 2998.85 | D13: 90 | E13: 49 | F13: 41 | H13: COFORGE | I13: 129.04 | J13: 87 | K13: 44 | L13: 43
B14: MPHASIS | C14: 979.85 | D14: 87 | E14: 45 | F14: 42 | H14: MPHASIS | I14: 2396.24 | J14: 84 | K14: 50 | L14: 34
B15: HEXT | C15: 4991.1 | D15: 99 | E15: 58 | F15: 41 | H15: HEXT | I15: 2110.19 | J15: 90 | K15: 47 | L15: 43
D16: =SUM(D6:D15) -> 800 | E16: =SUM(E6:E15) -> 416 | F16: =SUM(F6:F15) -> 384 | J16: =SUM(J6:J15) -> 784 | K16: =SUM(K6:K15) -> 409 | L16: =SUM(L6:L15) -> 375
B18: Q2 | H18: Q2
B19: SYMBOL | C19: BACKTEST P&L | D19: TOTAL NUMBER OF TRADES | E19: NUMBER OF WINS | F19: NUMBER OF LOSSES | H19: SYMBOL | I19: BACKTEST P&L | J19: TOTAL NUMBER OF TRADES | K19: NUMBER OF WINS | L19: NUMBER OF LOSSES
B20: TCS | C20: -2381.79 | D20: 65 | E20: 25 | F20: 40 | H20: TCS | I20: 2746.69 | J20: 67 | K20: 42 | L20: 25
B21: INFY | C21: -928.2 | D21: 66 | E21: 32 | F21: 34 | H21: INFY | I21: 539.6 | J21: 66 | K21: 31 | L21: 35
B22: HCLTECH | C22: -112.74 | D22: 66 | E22: 33 | F22: 33 | H22: HCLTECH | I22: 1589.44 | J22: 66 | K22: 37 | L22: 29
B23: WIPRO | C23: -1863.67 | D23: 66 | E23: 24 | F23: 42 | H23: WIPRO | I23: 1391.44 | J23: 68 | K23: 38 | L23: 30
B24: TECHM | C24: -937.15 | D24: 70 | E24: 38 | F24: 32 | H24: TECHM | I24: 577.54 | J24: 66 | K24: 34 | L24: 32
B25: PERSISTENT | C25: -2583.09 | D25: 74 | E25: 33 | F25: 41 | H25: PERSISTENT | I25: 1358.19 | J25: 73 | K25: 43 | L25: 30
B26: OFSS | C26: -3613.99 | D26: 71 | E26: 28 | F26: 43 | H26: OFSS | I26: 2321.89 | J26: 76 | K26: 42 | L26: 34
B27: COFORGE | C27: -1712.04 | D27: 77 | E27: 34 | F27: 43 | H27: COFORGE | I27: 1949.64 | J27: 76 | K27: 44 | L27: 32
B28: MPHASIS | C28: 900.35 | D28: 79 | E28: 39 | F28: 40 | H28: MPHASIS | I28: 2226.19 | J28: 75 | K28: 44 | L28: 31
B29: HEXT | C29: -1594.69 | D29: 92 | E29: 42 | F29: 50 | H29: HEXT | I29: 3625.39 | J29: 85 | K29: 49 | L29: 36
D30: =SUM(D20:D29) -> 726 | E30: =SUM(E20:E29) -> 328 | F30: =SUM(F20:F29) -> 398 | J30: =SUM(J20:J29) -> 718 | K30: =SUM(K20:K29) -> 404 | L30: =SUM(L20:L29) -> 314
B32: Q3 | H32: Q3
B33: SYMBOL | C33: BACKTEST P&L | D33: TOTAL NUMBER OF TRADES | E33: NUMBER OF WINS | F33: NUMBER OF LOSSES | H33: SYMBOL | I33: BACKTEST P&L | J33: TOTAL NUMBER OF TRADES | K33: NUMBER OF WINS | L33: NUMBER OF LOSSES
B34: TCS | C34: 1636.19 | D34: 62 | E34: 33 | F34: 29 | H34: TCS | I34: -1918.69 | J34: 62 | K34: 29 | L34: 33
B35: INFY | C35: 476.79 | D35: 61 | E35: 35 | F35: 26 | H35: INFY | I35: -1875.79 | J35: 62 | K35: 24 | L35: 38
B36: HCLTECH | C36: 878.05 | D36: 62 | E36: 33 | F36: 29 | H36: HCLTECH | I36: -1542 | J36: 65 | K36: 27 | L36: 38
B37: WIPRO | C37: 692.93 | D37: 62 | E37: 32 | F37: 30 | H37: WIPRO | I37: -1716.56 | J37: 64 | K37: 32 | L37: 32
B38: TECHM | C38: 1686.45 | D38: 65 | E38: 34 | F38: 31 | H38: TECHM | I38: -1700.6 | J38: 63 | K38: 29 | L38: 34
B39: PERSISTENT | C39: 2369.9 | D39: 67 | E39: 39 | F39: 28 | H39: PERSISTENT | I39: -2262.29 | J39: 68 | K39: 27 | L39: 41
B40: OFSS | C40: -2011.09 | D40: 71 | E40: 29 | F40: 42 | H40: OFSS | I40: 1839.19 | J40: 68 | K40: 34 | L40: 34
B41: COFORGE | C41: 1692.2 | D41: 74 | E41: 35 | F41: 39 | H41: COFORGE | I41: 505.14 | J41: 73 | K41: 39 | L41: 34
B42: MPHASIS | C42: 1918.45 | D42: 68 | E42: 39 | F42: 29 | H42: MPHASIS | I42: -1319.8 | J42: 69 | K42: 34 | L42: 35
B43: HEXT | C43: 5507.5 | D43: 85 | E43: 49 | F43: 36 | H43: HEXT | I43: -5134.115 | J43: 79 | K43: 33 | L43: 46
...

Sheet PP
B1: IT SECTOR
B3: BUY | H3: SELL
B4: Q1 | H4: Q1
B5: SYMBOL | C5: BACKTEST P&L | D5: TOTAL NUMBER OF TRADES | E5: NUMBER OF WINS | F5: NUMBER OF LOSSES | H5: SYMBOL | I5: BACKTEST P&L | J5: TOTAL NUMBER OF TRADES | K5: NUMBER OF WINS | L5: NUMBER OF LOSSES
B6: TCS | C6: -187.39 | D6: 24 | E6: 11 | F6: =D6-E6 -> 13 | H6: TCS | I6: 819.59 | J6: 25 | K6: 12 | L6: 19
B7: INFY | C7: -370.44 | D7: 31 | E7: 11 | F7: =D7-E7 -> 20 | H7: INFY | I7: -432.3 | J7: 38 | K7: 17 | L7: =J7-K7 -> 21
B8: HCLTECH | C8: -852.84 | D8: 33 | E8: 10 | F8: =D8-E8 -> 23 | H8: HCLTECH | I8: 202.34 | J8: 20 | K8: 16 | L8: =J8-K8 -> 4
B9: WIPRO | C9: -1812.05 | D9: 33 | E9: 10 | F9: =D9-E9 -> 23 | H9: WIPRO | I9: 487.01 | J9: 36 | K9: 22 | L9: =J9-K9 -> 14
B10: TECHM | C10: -956.89 | D10: 36 | E10: 14 | F10: =D10-E10 -> 22 | H10: TECHM | I10: -1689.25 | J10: 42 | K10: 18 | L10: =J10-K10 -> 24
B11: PERSISTENT | C11: 1707.35 | D11: 28 | E11: 14 | F11: =D11-E11 -> 14 | H11: PERSISTENT | I11: 1226.24 | J11: 28 | K11: 14 | L11: =J11-K11 -> 14
B12: OFSS | C12: 656.55 | D12: 31 | E12: 13 | F12: =D12-E12 -> 18 | H12: OFSS | I12: -1233.95 | J12: 35 | K12: 13 | L12: =J12-K12 -> 22
B13: COFORGE | C13: -1483.09 | D13: 40 | E13: 13 | F13: =D13-E13 -> 27 | H13: COFORGE | I13: 204.39 | J13: 41 | K13: 19 | L13: =J13-K13 -> 22
B14: MPHASIS | C14: 1742 | D14: 34 | E14: 17 | F14: =D14-E14 -> 17 | H14: MPHASIS | I14: -1174.45 | J14: 36 | K14: 14 | L14: =J14-K14 -> 22
B15: HEXT | C15: 1731.55 | D15: 35 | E15: 15 | F15: =D15-E15 -> 20 | H15: HEXT | I15: -1507.9 | J15: 38 | K15: 10 | L15: =J15-K15 -> 28
D16: =SUM(D6:D15) -> 325 | E16: =SUM(E6:E15) -> 128 | F16: =SUM(F6:F15) -> 197 | J16: =SUM(J6:J15) -> 339 | K16: =SUM(K6:K15) -> 155 | L16: =SUM(L6:L15) -> 190
B18: Q2 | H18: Q2
B19: SYMBOL | C19: BACKTEST P&L | D19: TOTAL NUMBER OF TRADES | E19: NUMBER OF WINS | F19: NUMBER OF LOSSES | H19: SYMBOL | I19: BACKTEST P&L | J19: TOTAL NUMBER OF TRADES | K19: NUMBER OF WINS | L19: NUMBER OF LOSSES
B20: TCS | C20: 305.6 | D20: 16 | E20: 6 | F20: =D20-E20 -> 10 | H20: TCS | I20: -40.75 | J20: 16 | K20: 8 | L20: =J20-K20 -> 8
B21: INFY | C21: 345.95 | D21: 18 | E21: 8 | F21: =D21-E21 -> 10 | H21: INFY | I21: 1217.5 | J21: 20 | K21: 13 | L21: =J21-K21 -> 7
B22: HCLTECH | C22: 296.8 | D22: 15 | E22: 7 | F22: =D22-E22 -> 8 | H22: HCLTECH | I22: 84.54 | J22: 18 | K22: 9 | L22: =J22-K22 -> 9
B23: WIPRO | C23: -1166.91 | D23: 23 | E23: 8 | F23: =D23-E23 -> 15 | H23: WIPRO | I23: 795.59 | J23: 23 | K23: 15 | L23: =J23-K23 -> 8
B24: TECHM | C24: 218.15 | D24: 22 | E24: 11 | F24: =D24-E24 -> 11 | H24: TECHM | I24: -794.2 | J24: 24 | K24: 11 | L24: =J24-K24 -> 13
B25: PERSISTENT | C25: 341 | D25: 18 | E25: 8 | F25: =D25-E25 -> 10 | H25: PERSISTENT | I25: -20 | J25: 26 | K25: 11 | L25: =J25-K25 -> 15
B26: OFSS | C26: -100.59 | D26: 18 | E26: 9 | F26: =D26-E26 -> 9 | H26: OFSS | I26: -41.2 | J26: 23 | K26: 8 | L26: =J26-K26 -> 15
B27: COFORGE | C27: -1337.79 | D27: 31 | E27: 10 | F27: =D27-E27 -> 21 | H27: COFORGE | I27: 773.39 | J27: 32 | K27: 17 | L27: =J27-K27 -> 15
B28: MPHASIS | C28: 72.05 | D28: 21 | E28: 9 | F28: =D28-E28 -> 12 | H28: MPHASIS | I28: 806.99 | J28: 24 | K28: 13 | L28: =J28-K28 -> 11
B29: HEXT | C29: 1191.75 | D29: 25 | E29: 10 | F29: =D29-E29 -> 15 | H29: HEXT | I29: 259.24 | J29: 32 | K29: 15 | L29: =J29-K29 -> 17
D30: =SUM(D20:D29) -> 207 | E30: =SUM(E20:E29) -> 86 | F30: =SUM(F20:F29) -> 121 | J30: =SUM(J20:J29) -> 238 | K30: =SUM(K20:K29) -> 120 | L30: =SUM(L20:L29) -> 118
B32: Q3 | H32: Q3
B33: SYMBOL | C33: BACKTEST P&L | D33: TOTAL NUMBER OF TRADES | E33: NUMBER OF WINS | F33: NUMBER OF LOSSES | H33: SYMBOL | I33: BACKTEST P&L | J33: TOTAL NUMBER OF TRADES | K33: NUMBER OF WINS | L33: NUMBER OF LOSSES
B34: TCS | C34: 2397.7 | D34: 27 | E34: 15 | F34: =D34-E34 -> 12 | H34: TCS | I34: 31.55 | J34: 31 | K34: 16 | L34: =J34-K34 -> 15
B35: INFY | C35: -127.39 | D35: 27 | E35: 12 | F35: =D35-E35 -> 15 | H35: INFY | I35: -283.7 | J35: 31 | K35: 12 | L35: =J35-K35 -> 19
B36: HCLTECH | C36: 1051.1 | D36: 30 | E36: 18 | F36: =D36-E36 -> 12 | H36: HCLTECH | I36: -1486.5 | J36: 37 | K36: 13 | L36: =J36-K36 -> 24
B37: WIPRO | C37: 683.4 | D37: 13 | E37: 29 | F37: =D37-E37 -> -16 | H37: WIPRO | I37: -551.4 | J37: 34 | K37: 16 | L37: =J37-K37 -> 18
B38: TECHM | C38: 1022.74 | D38: 25 | E38: 14 | F38: =D38-E38 -> 11 | H38: TECHM | I38: -394.9 | J38: 30 | K38: 13 | L38: =J38-K38 -> 17
B39: PERSISTENT | C39: 104.35 | D39: 20 | E39: 8 | F39: =D39-E39 -> 12 | H39: PERSISTENT | I39: 74.69 | J39: 28 | K39: 15 | L39: =J39-K39 -> 13
B40: OFSS | C40: 203 | D40: 25 | E40: 13 | F40: =D40-E40 -> 12 | H40: OFSS | I40: -1613.65 | J40: 32 | K40: 12 | L40: =J40-K40 -> 20
B41: COFORGE | C41: 572.1 | D41: 25 | E41: 12 | F41: =D41-E41 -> 13 | H41: COFORGE | I41: -917.45 | J41: 28 | K41: 9 | L41: =J41-K41 -> 19
B42: MPHASIS | C42: -445.49 | D42: 30 | E42: 12 | F42: =D42-E42 -> 18 | H42: MPHASIS | I42: -149.05 | J42: 35 | K42: 16 | L42: =J42-K42 -> 19
B43: HEXT | C43: 1985.7 | D43: 25 | E43: 14 | F43: =D43-E43 -> 11 | H43: HEXT | I43: -243.25 | J43: 34 | K43: 12 | L43: =J43-K43 -> 22
...

Sheet Awesome
B1: IT SECTOR
B3: BUY | H3: SELL
B4: Q1 | H4: Q1
B5: SYMBOL | C5: BACKTEST P&L | D5: TOTAL NUMBER OF TRADES | E5: NUMBER OF WINS | F5: NUMBER OF LOSSES | H5: SYMBOL | I5: BACKTEST P&L | J5: TOTAL NUMBER OF TRADES | K5: NUMBER OF WINS | L5: NUMBER OF LOSSES
B6: TCS | C6: -514.84 | D6: 62 | E6: 27 | F6: =D6-E6 -> 35 | H6: TCS | I6: 467.09 | J6: 60 | K6: 30 | L6: 19
B7: INFY | C7: 1172.9 | D7: 57 | E7: 33 | F7: =D7-E7 -> 24 | H7: INFY | I7: -906.8 | J7: 67 | K7: 31 | L7: =J7-K7 -> 36
B8: HCLTECH | C8: 1008.55 | D8: 58 | E8: 29 | F8: =D8-E8 -> 29 | H8: HCLTECH | I8: -731.4 | J8: 68 | K8: 34 | L8: =J8-K8 -> 34
B9: WIPRO | C9: 1064.69 | D9: 60 | E9: 31 | F9: =D9-E9 -> 29 | H9: WIPRO | I9: -1789.26 | J9: 64 | K9: 25 | L9: =J9-K9 -> 39
B10: TECHM | C10: 896.1 | D10: 67 | E10: 32 | F10: =D10-E10 -> 35 | H10: TECHM | I10: -1081.05 | J10: 64 | K10: 28 | L10: =J10-K10 -> 36
B11: PERSISTENT | C11: 1302.65 | D11: 72 | E11: 35 | F11: =D11-E11 -> 37 | H11: PERSISTENT | I11: 1573.84 | J11: 74 | K11: 40 | L11: =J11-K11 -> 34
B12: OFSS | C12: -242.74 | D12: 76 | E12: 31 | F12: =D12-E12 -> 45 | H12: OFSS | I12: -71.8 | J12: 73 | K12: 32 | L12: =J12-K12 -> 41
B13: COFORGE | C13: 3397.6 | D13: 66 | E13: 38 | F13: =D13-E13 -> 28 | H13: COFORGE | I13: -778.8 | J13: 71 | K13: 30 | L13: =J13-K13 -> 41
B14: MPHASIS | C14: 2419.8 | D14: 67 | E14: 36 | F14: =D14-E14 -> 31 | H14: MPHASIS | I14: -180.55 | J14: 68 | K14: 31 | L14: =J14-K14 -> 37
B15: HEXT | C15: 3513.95 | D15: 65 | E15: 34 | F15: =D15-E15 -> 31 | H15: HEXT | I15: -4009.2 | J15: 77 | K15: 24 | L15: =J15-K15 -> 53
D16: =SUM(D6:D15) -> 650 | E16: =SUM(E6:E15) -> 326 | F16: =SUM(F6:F15) -> 324 | J16: =SUM(J6:J15) -> 686 | K16: =SUM(K6:K15) -> 305 | L16: =SUM(L6:L15) -> 370
B18: Q2 | H18: Q2
B19: SYMBOL | C19: BACKTEST P&L | D19: TOTAL NUMBER OF TRADES | E19: NUMBER OF WINS | F19: NUMBER OF LOSSES | H19: SYMBOL | I19: BACKTEST P&L | J19: TOTAL NUMBER OF TRADES | K19: NUMBER OF WINS | L19: NUMBER OF LOSSES
B20: TCS | C20: -1384.64 | D20: 60 | E20: 23 | F20: =D20-E20 -> 37 | H20: TCS | I20: 2066.8 | J20: 57 | K20: 37 | L20: =J20-K20 -> 20
B21: INFY | C21: 596.94 | D21: 65 | E21: 31 | F21: =D21-E21 -> 34 | H21: INFY | I21: 541.54 | J21: 59 | K21: 33 | L21: =J21-K21 -> 26
B22: HCLTECH | C22: -815.69 | D22: 63 | E22: 28 | F22: =D22-E22 -> 35 | H22: HCLTECH | I22: 2713.14 | J22: 59 | K22: 38 | L22: =J22-K22 -> 21
B23: WIPRO | C23: -93.17 | D23: 67 | E23: 30 | F23: =D23-E23 -> 37 | H23: WIPRO | I23: 725.53 | J23: 65 | K23: 37 | L23: =J23-K23 -> 28
B24: TECHM | C24: -120.14 | D24: 59 | E24: 27 | F24: =D24-E24 -> 32 | H24: TECHM | I24: -777.9 | J24: 66 | K24: 25 | L24: =J24-K24 -> 41
B25: PERSISTENT | C25: -1591.49 | D25: 69 | E25: 29 | F25: =D25-E25 -> 40 | H25: PERSISTENT | I25: 715.14 | J25: 69 | K25: 35 | L25: =J25-K25 -> 34
B26: OFSS | C26: 181.55 | D26: 63 | E26: 28 | F26: =D26-E26 -> 35 | H26: OFSS | I26: 78.14 | J26: 64 | K26: 31 | L26: =J26-K26 -> 33
B27: COFORGE | C27: 548.45 | D27: 69 | E27: 32 | F27: =D27-E27 -> 37 | H27: COFORGE | I27: 1673.44 | J27: 69 | K27: 36 | L27: =J27-K27 -> 33
B28: MPHASIS | C28: -1102.39 | D28: 77 | E28: 31 | F28: =D28-E28 -> 46 | H28: MPHASIS | I28: 2045.39 | J28: 67 | K28: 34 | L28: =J28-K28 -> 33
B29: HEXT | C29: 3379.2 | D29: 65 | E29: 32 | F29: =D29-E29 -> 33 | H29: HEXT | I29: 3136.09 | J29: 64 | K29: 35 | L29: =J29-K29 -> 29
D30: =SUM(D20:D29) -> 657 | E30: =SUM(E20:E29) -> 291 | F30: =SUM(F20:F29) -> 366 | J30: =SUM(J20:J29) -> 639 | K30: =SUM(K20:K29) -> 341 | L30: =SUM(L20:L29) -> 298
B32: Q3 | H32: Q3
B33: SYMBOL | C33: BACKTEST P&L | D33: TOTAL NUMBER OF TRADES | E33: NUMBER OF WINS | F33: NUMBER OF LOSSES | H33: SYMBOL | I33: BACKTEST P&L | J33: TOTAL NUMBER OF TRADES | K33: NUMBER OF WINS | L33: NUMBER OF LOSSES
B34: TCS | C34: 146.7 | D34: 66 | E34: 30 | F34: =D34-E34 -> 36 | H34: TCS | I34: -587.95 | J34: 61 | K34: 30 | L34: =J34-K34 -> 31
B35: INFY | C35: -168 | D35: 58 | E35: 33 | F35: =D35-E35 -> 25 | H35: INFY | I35: -152.6 | J35: 58 | K35: 23 | L35: =J35-K35 -> 35
B36: HCLTECH | C36: 462.25 | D36: 59 | E36: 30 | F36: =D36-E36 -> 29 | H36: HCLTECH | I36: -1455.35 | J36: 64 | K36: 37 | L36: =J36-K36 -> 27
B37: WIPRO | C37: 655.52 | D37: 60 | E37: 28 | F37: =D37-E37 -> 32 | H37: WIPRO | I37: -448.77 | J37: 63 | K37: 27 | L37: =J37-K37 -> 36
B38: TECHM | C38: 1499.09 | D38: 63 | E38: 33 | F38: =D38-E38 -> 30 | H38: TECHM | I38: -1002.19 | J38: 62 | K38: 30 | L38: =J38-K38 -> 32
B39: PERSISTENT | C39: -527.04 | D39: 58 | E39: 26 | F39: =D39-E39 -> 32 | H39: PERSISTENT | I39: 1678.54 | J39: 65 | K39: 32 | L39: =J39-K39 -> 33
B40: OFSS | C40: 1192.95 | D40: 67 | E40: 33 | F40: =D40-E40 -> 34 | H40: OFSS | I40: -1253.45 | J40: 64 | K40: 27 | L40: =J40-K40 -> 37
B41: COFORGE | C41: -527.54 | D41: 70 | E41: 33 | F41: =D41-E41 -> 37 | H41: COFORGE | I41: -1885.65 | J41: 76 | K41: 32 | L41: =J41-K41 -> 44
B42: MPHASIS | C42: 686.15 | D42: 73 | E42: 34 | F42: =D42-E42 -> 39 | H42: MPHASIS | I42: 51.84 | J42: 70 | K42: 30 | L42: =J42-K42 -> 40
B43: HEXT | C43: 3453.15 | D43: 65 | E43: 33 | F43: =D43-E43 -> 32 | H43: HEXT | I43: 970.14 | J43: 60 | K43: 29 | L43: =J43-K43 -> 31
...

Sheet Bollinger
B1: IT SECTOR
B3: BUY | H3: SELL
B4: Q1 | H4: Q1
B5: SYMBOL | C5: BACKTEST P&L | D5: TOTAL NUMBER OF TRADES | E5: NUMBER OF WINS | F5: NUMBER OF LOSSES | H5: SYMBOL | I5: BACKTEST P&L | J5: TOTAL NUMBER OF TRADES | K5: NUMBER OF WINS | L5: NUMBER OF LOSSES
B6: TCS | C6: 474.7 | D6: 60 | E6: 30 | F6: =D6-E6 -> 30 | H6: TCS | I6: -1567 | J6: 63 | K6: 25 | L6: 19
B7: INFY | C7: 393.75 | D7: 66 | E7: 37 | F7: =D7-E7 -> 29 | H7: INFY | I7: -1073.8 | J7: 67 | K7: 36 | L7: =J7-K7 -> 31
B8: HCLTECH | C8: 651 | D8: 62 | E8: 31 | F8: =D8-E8 -> 31 | H8: HCLTECH | I8: -1283.15 | J8: 74 | K8: 30 | L8: =J8-K8 -> 44
B9: WIPRO | C9: 3410.05 | D9: 65 | E9: 39 | F9: =D9-E9 -> 26 | H9: WIPRO | I9: -492.95 | J9: 63 | K9: 29 | L9: =J9-K9 -> 34
B10: TECHM | C10: 2504.9 | D10: 68 | E10: 39 | F10: =D10-E10 -> 29 | H10: TECHM | I10: 615.49 | J10: 75 | K10: 38 | L10: =J10-K10 -> 37
B11: PERSISTENT | C11: -757.64 | D11: 68 | E11: 28 | F11: =D11-E11 -> 40 | H11: PERSISTENT | I11: 2096.09 | J11: 80 | K11: 41 | L11: =J11-K11 -> 39
B12: OFSS | C12: 1498.55 | D12: 70 | E12: 34 | F12: =D12-E12 -> 36 | H12: OFSS | I12: -9.05 | J12: 80 | K12: 33 | L12: =J12-K12 -> 47
B13: COFORGE | C13: 1400 | D13: 66 | E13: 34 | F13: =D13-E13 -> 32 | H13: COFORGE | I13: 830.54 | J13: 86 | K13: 40 | L13: =J13-K13 -> 46
B14: MPHASIS | C14: 255.85 | D14: 70 | E14: 31 | F14: =D14-E14 -> 39 | H14: MPHASIS | I14: -1547.3 | J14: 79 | K14: 30 | L14: =J14-K14 -> 49
B15: HEXT | C15: 4726.88 | D15: 82 | E15: 40 | F15: =D15-E15 -> 42 | H15: HEXT | I15: -4590.1 | J15: 78 | K15: 27 | L15: =J15-K15 -> 51
D16: =SUM(D6:D15) -> 677 | E16: =SUM(E6:E15) -> 343 | F16: =SUM(F6:F15) -> 334 | J16: =SUM(J6:J15) -> 745 | K16: =SUM(K6:K15) -> 329 | L16: =SUM(L6:L15) -> 397
B18: Q2 | H18: Q2
B19: SYMBOL | C19: BACKTEST P&L | D19: TOTAL NUMBER OF TRADES | E19: NUMBER OF WINS | F19: NUMBER OF LOSSES | H19: SYMBOL | I19: BACKTEST P&L | J19: TOTAL NUMBER OF TRADES | K19: NUMBER OF WINS | L19: NUMBER OF LOSSES
B20: TCS | C20: -3095.39 | D20: 67 | E20: 20 | F20: =D20-E20 -> 47 | H20: TCS | I20: 92.24 | J20: 57 | K20: 31 | L20: =J20-K20 -> 26
B21: INFY | C21: -1743.54 | D21: 72 | E21: 31 | F21: =D21-E21 -> 41 | H21: INFY | I21: 493.94 | J21: 63 | K21: 32 | L21: =J21-K21 -> 31
B22: HCLTECH | C22: -1281.84 | D22: 72 | E22: 29 | F22: =D22-E22 -> 43 | H22: HCLTECH | I22: 582.04 | J22: 58 | K22: 33 | L22: =J22-K22 -> 25
B23: WIPRO | C23: -746.36 | D23: 69 | E23: 26 | F23: =D23-E23 -> 43 | H23: WIPRO | I23: 541.89 | J23: 62 | K23: 31 | L23: =J23-K23 -> 31
B24: TECHM | C24: -1227.54 | D24: 72 | E24: 31 | F24: =D24-E24 -> 41 | H24: TECHM | I24: 72.74 | J24: 63 | K24: 27 | L24: =J24-K24 -> 36
B25: PERSISTENT | C25: -219.29 | D25: 76 | E25: 34 | F25: =D25-E25 -> 42 | H25: PERSISTENT | I25: 846.64 | J25: 32 | K25: 71 | L25: =J25-K25 -> -39
B26: OFSS | C26: -2917.84 | D26: 77 | E26: 29 | F26: =D26-E26 -> 48 | H26: OFSS | I26: -343.8 | J26: 61 | K26: 28 | L26: =J26-K26 -> 33
B27: COFORGE | C27: 286.6 | D27: 84 | E27: 36 | F27: =D27-E27 -> 48 | H27: COFORGE | I27: 403.44 | J27: 67 | K27: 38 | L27: =J27-K27 -> 29
B28: MPHASIS | C28: -2045.34 | D28: 72 | E28: 23 | F28: =D28-E28 -> 49 | H28: MPHASIS | I28: 469.54 | J28: 78 | K28: 35 | L28: =J28-K28 -> 43
B29: HEXT | C29: -676.39 | D29: 85 | E29: 32 | F29: =D29-E29 -> 53 | H29: HEXT | I29: -1696.5 | J29: 77 | K29: 27 | L29: =J29-K29 -> 50
D30: =SUM(D20:D29) -> 746 | E30: =SUM(E20:E29) -> 291 | F30: =SUM(F20:F29) -> 455 | J30: =SUM(J20:J29) -> 618 | K30: =SUM(K20:K29) -> 353 | L30: =SUM(L20:L29) -> 265
B32: Q3 | H32: Q3
B33: SYMBOL | C33: BACKTEST P&L | D33: TOTAL NUMBER OF TRADES | E33: NUMBER OF WINS | F33: NUMBER OF LOSSES | H33: SYMBOL | I33: BACKTEST P&L | J33: TOTAL NUMBER OF TRADES | K33: NUMBER OF WINS | L33: NUMBER OF LOSSES
B34: TCS | C34: -234.99 | D34: 55 | E34: 28 | F34: =D34-E34 -> 27 | H34: TCS | I34: -1204.15 | J34: 61 | K34: 28 | L34: =J34-K34 -> 33
B35: INFY | C35: -1253.54 | D35: 57 | E35: 28 | F35: =D35-E35 -> 29 | H35: INFY | I35: -1069.05 | J35: 71 | K35: 31 | L35: =J35-K35 -> 40
B36: HCLTECH | C36: 719.2 | D36: 57 | E36: 32 | F36: =D36-E36 -> 25 | H36: HCLTECH | I36: -525.4 | J36: 68 | K36: 35 | L36: =J36-K36 -> 33
B37: WIPRO | C37: 467.09 | D37: 52 | E37: 28 | F37: =D37-E37 -> 24 | H37: WIPRO | I37: -703 | J37: 57 | K37: 30 | L37: =J37-K37 -> 27
B38: TECHM | C38: 126.45 | D38: 61 | E38: 28 | F38: =D38-E38 -> 33 | H38: TECHM | I38: -551.59 | J38: 64 | K38: 28 | L38: =J38-K38 -> 36
B39: PERSISTENT | C39: -2627.59 | D39: 65 | E39: 25 | F39: =D39-E39 -> 40 | H39: PERSISTENT | I39: 1160.64 | J39: 64 | K39: 34 | L39: =J39-K39 -> 30
B40: OFSS | C40: -1153.44 | D40: 56 | E40: 23 | F40: =D40-E40 -> 33 | H40: OFSS | I40: -2848.5 | J40: 72 | K40: 25 | L40: =J40-K40 -> 47
B41: COFORGE | C41: 2377.4 | D41: 71 | E41: 39 | F41: =D41-E41 -> 32 | H41: COFORGE | I41: 725.89 | J41: 73 | K41: 34 | L41: =J41-K41 -> 39
B42: MPHASIS | C42: -634.49 | D42: 61 | E42: 32 | F42: =D42-E42 -> 29 | H42: MPHASIS | I42: -1373.4 | J42: 67 | K42: 27 | L42: =J42-K42 -> 40
B43: HEXT | C43: -1130.69 | D43: 66 | E43: 25 | F43: =D43-E43 -> 41 | H43: HEXT | I43: -4339.95 | J43: 84 | K43: 29 | L43: =J43-K43 -> 55
...

Sheet CP
B1: IT SECTOR
B3: BUY | H3: SELL
B4: Q1 | H4: Q1
B5: SYMBOL | C5: BACKTEST P&L | D5: TOTAL NUMBER OF TRADES | E5: NUMBER OF WINS | F5: NUMBER OF LOSSES | H5: SYMBOL | I5: BACKTEST P&L | J5: TOTAL NUMBER OF TRADES | K5: NUMBER OF WINS | L5: NUMBER OF LOSSES
B6: TCS | C6: 627.15 | D6: 36 | E6: 19 | F6: 17 | H6: TCS | I6: -724.35 | J6: 35 | K6: 14 | L6: 20
B7: INFY | C7: 1925.5 | D7: 39 | E7: 23 | F7: 16 | H7: INFY | I7: -1448.49 | J7: 32 | K7: 11 | L7: 21
B8: HCLTECH | C8: 225.45 | D8: 41 | E8: 22 | F8: 19 | H8: HCLTECH | I8: -2087.75 | J8: 35 | K8: 13 | L8: 21
B9: WIPRO | C9: 85.89 | D9: 41 | E9: 20 | F9: 21 | H9: WIPRO | I9: -1793.51 | J9: 37 | K9: 16 | L9: 21
B10: TECHM | C10: 1784.6 | D10: 37 | E10: 23 | F10: 14 | H10: TECHM | I10: -1303.89 | J10: 29 | K10: 14 | L10: 15
B11: PERSISTENT | C11: 235.45 | D11: 37 | E11: 19 | F11: 18 | H11: PERSISTENT | I11: -567.55 | J11: 36 | K11: 17 | L11: 19
B12: OFSS | C12: -1678 | D12: 59 | E12: 16 | F12: 23 | H12: OFSS | I12: 527.24 | J12: 32 | K12: 19 | L12: 13
B13: COFORGE | C13: -43.54 | D13: 37 | E13: 21 | F13: 16 | H13: COFORGE | I13: -2274.5 | J13: 29 | K13: 12 | L13: 17
B14: MPHASIS | C14: 397.45 | D14: 40 | E14: 19 | F14: 21 | H14: MPHASIS | I14: -2024.35 | J14: 33 | K14: 13 | L14: 20
B15: HEXT | C15: 5887.35 | D15: 43 | E15: 32 | F15: 11 | H15: HEXT | I15: -3539.4 | J15: 42 | K15: 18 | L15: 24
D16: =SUM(D6:D15) -> 410 | E16: =SUM(E6:E15) -> 214 | F16: =SUM(F6:F15) -> 176 | J16: =SUM(J6:J15) -> 340 | K16: =SUM(K6:K15) -> 147 | L16: =SUM(L6:L15) -> 191
B18: Q2 | H18: Q2
B19: SYMBOL | C19: BACKTEST P&L | D19: TOTAL NUMBER OF TRADES | E19: NUMBER OF WINS | F19: NUMBER OF LOSSES | H19: SYMBOL | I19: BACKTEST P&L | J19: TOTAL NUMBER OF TRADES | K19: NUMBER OF WINS | L19: NUMBER OF LOSSES
B20: TCS | C20: -1359.9 | D20: 36 | E20: 13 | F20: 23 | H20: TCS | I20: 1434.39 | J20: 33 | K20: 24 | L20: 9
B21: INFY | C21: -1128.89 | D21: 35 | E21: 15 | F21: 20 | H21: INFY | I21: -515.15 | J21: 35 | K21: 16 | L21: 19
B22: HCLTECH | C22: -719.74 | D22: 38 | E22: 19 | F22: 19 | H22: HCLTECH | I22: -397.45 | J22: 31 | K22: 13 | L22: 18
B23: WIPRO | C23: 317.86 | D23: 35 | E23: 18 | F23: 17 | H23: WIPRO | I23: -366.32 | J23: 31 | K23: 15 | L23: 16
B24: TECHM | C24: -361.19 | D24: 40 | E24: 18 | F24: 22 | H24: TECHM | I24: 41.79 | J24: 37 | K24: 17 | L24: 20
B25: PERSISTENT | C25: -1850.59 | D25: 37 | E25: 15 | F25: 22 | H25: PERSISTENT | I25: -1273.2 | J25: 32 | K25: 14 | L25: 18
B26: OFSS | C26: -830.49 | D26: 41 | E26: 21 | F26: 20 | H26: OFSS | I26: 161.55 | J26: 38 | K26: 19 | L26: 19
B27: COFORGE | C27: -678.04 | D27: 39 | E27: 19 | F27: 20 | H27: COFORGE | I27: 1070.04 | J27: 33 | K27: 18 | L27: 14
B28: MPHASIS | C28: -1816.69 | D28: 44 | E28: 16 | F28: 28 | H28: MPHASIS | I28: 1418.39 | J28: 33 | K28: 23 | L28: 10
B29: HEXT | C29: -2208.79 | D29: 45 | E29: 19 | F29: 26 | H29: HEXT | I29: 4016.59 | J29: 34 | K29: 24 | L29: 10
D30: =SUM(D20:D29) -> 390 | E30: =SUM(E20:E29) -> 173 | F30: =SUM(F20:F29) -> 217 | J30: =SUM(J20:J29) -> 337 | K30: =SUM(K20:K29) -> 183 | L30: =SUM(L20:L29) -> 153
B32: Q3 | H32: Q3
B33: SYMBOL | C33: BACKTEST P&L | D33: TOTAL NUMBER OF TRADES | E33: NUMBER OF WINS | F33: NUMBER OF LOSSES | H33: SYMBOL | I33: BACKTEST P&L | J33: TOTAL NUMBER OF TRADES | K33: NUMBER OF WINS | L33: NUMBER OF LOSSES
B34: TCS | C34: 700.1 | D34: 40 | E34: 17 | F34: 23 | H34: TCS | I34: -3.79 | J34: 32 | K34: 15 | L34: 17
B35: INFY | C35: -451.2 | D35: 30 | E35: 14 | F35: 16 | H35: INFY | I35: -48.09 | J35: 29 | K35: 14 | L35: 15
B36: HCLTECH | C36: 1360.05 | D36: 36 | E36: 20 | F36: 16 | H36: HCLTECH | I36: -1466.4 | J36: 35 | K36: 15 | L36: 20
B37: WIPRO | C37: 1590.83 | D37: 32 | E37: 20 | F37: 12 | H37: WIPRO | I37: -1319.14 | J37: 32 | K37: 13 | L37: 19
B38: TECHM | C38: 1474.09 | D38: 38 | E38: 24 | F38: 14 | H38: TECHM | I38: -1623.2 | J38: 35 | K38: 14 | L38: 21
B39: PERSISTENT | C39: 47.05 | D39: 39 | E39: 21 | F39: 18 | H39: PERSISTENT | I39: -1126.85 | J39: 33 | K39: 15 | L39: 18
B40: OFSS | C40: -1109.49 | D40: 35 | E40: 15 | F40: 20 | H40: OFSS | I40: 2134.89 | J40: 30 | K40: 20 | L40: 10
B41: COFORGE | C41: -2034.89 | D41: 45 | E41: 20 | F41: 25 | H41: COFORGE | I41: -1742.85 | J41: 40 | K41: 16 | L41: 24
B42: MPHASIS | C42: 699.65 | D42: 38 | E42: 21 | F42: 17 | H42: MPHASIS | I42: -761.6 | J42: 32 | K42: 15 | L42: 17
B43: HEXT | C43: 3830.5 | D43: 40 | E43: 27 | F43: 13 | H43: HEXT | I43: -1241.55 | J43: 34 | K43: 14 | L43: 20
...

Sheet RESULT
D3: Sr. No. | E3: Name | F3: Probability of Win | G3: Probability of Loss | H3: Ranking
D4: 1 | E4: RSI | F4: =RSI!D62 -> 0.45217391 | G4: =RSI!D63 -> 0.54782609 | H4: =_xlfn.RANK.EQ(F4, $F$4:$F$13, 0) -> 7
D5: 2 | E5: Supertrend | F5: =Supertrend!D62 -> 0.43789809 | G5: =Supertrend!D63 -> 0.56210191 | H5: =_xlfn.RANK.EQ(F5, $F$4:$F$13, 0) -> 8
D6: 3 | E6: MA | F6: =MA!D62 -> 0.47506822 | G6: =MA!D63 -> 0.52493178 | H6: =_xlfn.RANK.EQ(F6, $F$4:$F$13, 0) -> 4
D7: 4 | E7: VWAP | F7: =VWAP!D62 -> 0.43064413 | G7: =VWAP!D63 -> 0.56935587 | H7: =_xlfn.RANK.EQ(F7, $F$4:$F$13, 0) -> 10
D8: 5 | E8: MACD | F8: =MACD!D62 -> 0.43671556 | G8: =MACD!D63 -> 0.56328444 | H8: =_xlfn.RANK.EQ(F8, $F$4:$F$13, 0) -> 9
D9: 6 | E9: S_RSI | F9: ='Stochastic RSI'!D62 -> 0.50554808 | G9: ='Stochastic RSI'!D63 -> 0.49445192 | H9: =_xlfn.RANK.EQ(F9, $F$4:$F$13, 0) -> 1
D10: 7 | E10: PP | F10: =PP!D62 -> 0.45589601 | G10: =PP!D63 -> 0.54410399 | H10: =_xlfn.RANK.EQ(F10, $F$4:$F$13, 0) -> 6
D11: 8 | E11: Awesome Alligator | F11: =Awesome!D62 -> 0.47667999 | G11: =Awesome!D63 -> 0.52332001 | H11: =_xlfn.RANK.EQ(F11, $F$4:$F$13, 0) -> 3
D12: 9 | E12: Bollinger | F12: =Bollinger!D62 -> 0.46023138 | G12: =Bollinger!D63 -> 0.53976862 | H12: =_xlfn.RANK.EQ(F12, $F$4:$F$13, 0) -> 5
D13: 10 | E13: CP | F13: =CP!D62 -> 0.48679639 | G13: =CP!D63 -> 0.51320361 | H13: =_xlfn.RANK.EQ(F13, $F$4:$F$13, 0) -> 2
C14: CONCLUSION: The private bank sector stocks were backtested using 10 different technical indicators for a period of 1 year from 1st April 2025 to 31st March 2026. The indicators tested were RSI, Supertrend, VWAP, MA, MACD, S_RSI, Pivot Point (PP), Bollinger Bands, Awesome Alligator, and CP. Each indicator was evaluated based on its probability of win, probability of loss, and overall ranking. Based on the analysis, the S_RSI indicator showed the highest probability of win among all the indicators tested, with a win rate of 51% and a loss rate of only 49%, making it the top ranked indicator overall (Rank 1). This indicates that S_RSI was the most effective in identifying profitable trading opportunities and capturing trend movements in the private banking sector during the selected time period. The second best performing indicator was CP with a win rate of 49%, followed by MA and Awesome Alligator, both at 48%, ranked 3rd and 4th respectively. These indicators also showed relatively better performance compared to the others and can be considered reasonably reliable for trading in this sector. Indicators such as PP (46%) and Bollinger Bands (46%) showed similar win rates, ranked 5th and 6th respectively, suggesting moderate effectiveness in the private banking sector. RSI recorded a win rate of 45% and was ranked 7th, while Supertrend and MACD both recorded a win rate of 44%, ranked 8th and 9th respectively, indicating limited reliability during the studied period. VWAP recorded the lowest win rate of 43% and was ranked last (Rank 10) among all indicators, making it the least suitable indicator for trading in this sector during the studied time period.Therefore, the study concludes that S_RSI can be considered the most reliable and effective indicator for trading analysis in the private banking sector, as it outperformed all other indicators in terms of win probability. Traders and analysts focusing on private bank stocks may benefit most from incorporating S_RSI into their technical analysis framework during the studied period.
